Traceback (most recent call last):
  File "./globalfit.py", line 68, in <module>
    if rank==0:
NameError: name 'rank' is not defined
Traceback (most recent call last):
  File "./globalfit.py", line 68, in <module>
    if rank==0:
NameError: name 'rank' is not defined
Traceback (most recent call last):
  File "./globalfit.py", line 68, in <module>
    if rank==0:
NameError: name 'rank' is not defined
Traceback (most recent call last):
  File "./globalfit.py", line 68, in <module>
    if rank==0:
NameError: name 'rank' is not defined
Traceback (most recent call last):
  File "./globalfit.py", line 68, in <module>
    if rank==0:
NameError: name 'rank' is not defined
Traceback (most recent call last):
  File "./globalfit.py", line 68, in <module>
    if rank==0:
NameError: name 'rank' is not defined
Traceback (most recent call last):
  File "./globalfit.py", line 68, in <module>
    if rank==0:
NameError: name 'rank' is not defined
Traceback (most recent call last):
  File "./globalfit.py", line 68, in <module>
    if rank==0:
NameError: name 'rank' is not defined
Traceback (most recent call last):
  File "./globalfit.py", line 68, in <module>
    if rank==0:
NameError: name 'rank' is not defined
Traceback (most recent call last):
  File "./globalfit.py", line 68, in <module>
    if rank==0:
NameError: name 'rank' is not defined
--------------------------------------------------------------------------
Primary job  terminated normally, but 1 process returned
a non-zero exit code. Per user-direction, the job has been aborted.
--------------------------------------------------------------------------
--------------------------------------------------------------------------
mpirun detected that one or more processes exited with non-zero status, thus causing
the job to be terminated. The first process to do so was:

  Process name: [[15425,1],2]
  Exit code:    1
--------------------------------------------------------------------------
